Traceback (most recent call last):
  File "test-data-2.0/extras/testTraceback3.py", line 2, in <module>
    print([1,2,3][10])
IndexError: list index out of range