Traceback (most recent call last):
  File "test-data/testTypesCollections4.py", line 11, in <module>
    foo([func])
  File "test-data/testTypesCollections4.py", line 7, in foo
    res.append(f())
WyppTypeError: got value of wrong type
given:    42
expected: value of type str

context: __next__(self: Self) -> Callable[[], str]
                                              ^^^
declared at: test-data/testTypesCollections4.py:4
caused by: test-data/testTypesCollections4.py:4
  |     l.append(lambda: 42) # error
