Traceback (most recent call last):
  File "file-test-data/extras/testIndexError.py", line 6, in <module>
    foo([1,2,3])
  File "file-test-data/extras/testIndexError.py", line 3, in foo
    x = l[42]
IndexError: list index out of range